nohup: ignoring input
[2025-10-17 10:59:15 +0500] [237859] [INFO] Starting gunicorn 23.0.0
[2025-10-17 10:59:15 +0500] [237859] [INFO] Listening at: http://127.0.0.1:8009 (237859)
[2025-10-17 10:59:15 +0500] [237859] [INFO] Using worker: sync
[2025-10-17 10:59:15 +0500] [237861] [INFO] Booting worker with pid: 237861
[2025-10-17 10:59:15 +0500] [237861] [ERROR] Exception in worker process
Traceback (most recent call last):
  File "/home/javodev/Shaxobiddin/KatDPI_TEST/KatDPI_test/env/lib/python3.11/site-packages/gunicorn/arbiter.py", line 608, in spawn_worker
    worker.init_process()
  File "/home/javodev/Shaxobiddin/KatDPI_TEST/KatDPI_test/env/lib/python3.11/site-packages/gunicorn/workers/base.py", line 135, in init_process
    self.load_wsgi()
  File "/home/javodev/Shaxobiddin/KatDPI_TEST/KatDPI_test/env/lib/python3.11/site-packages/gunicorn/workers/base.py", line 147, in load_wsgi
    self.wsgi = self.app.wsgi()
                ^^^^^^^^^^^^^^^
  File "/home/javodev/Shaxobiddin/KatDPI_TEST/KatDPI_test/env/lib/python3.11/site-packages/gunicorn/app/base.py", line 66, in wsgi
    self.callable = self.load()
                    ^^^^^^^^^^^
  File "/home/javodev/Shaxobiddin/KatDPI_TEST/KatDPI_test/env/lib/python3.11/site-packages/gunicorn/app/wsgiapp.py", line 57, in load
    return self.load_wsgiapp()
           ^^^^^^^^^^^^^^^^^^^
  File "/home/javodev/Shaxobiddin/KatDPI_TEST/KatDPI_test/env/lib/python3.11/site-packages/gunicorn/app/wsgiapp.py", line 47, in load_wsgiapp
    return util.import_app(self.app_uri)
           ^^^^^^^^^^^^^^^^^^^^^^^^^^^^^
  File "/home/javodev/Shaxobiddin/KatDPI_TEST/KatDPI_test/env/lib/python3.11/site-packages/gunicorn/util.py", line 370, in import_app
    mod = importlib.import_module(module)
          ^^^^^^^^^^^^^^^^^^^^^^^^^^^^^^^
  File "/usr/lib/python3.11/importlib/__init__.py", line 126, in import_module
    return _bootstrap._gcd_import(name[level:], package, level)
           ^^^^^^^^^^^^^^^^^^^^^^^^^^^^^^^^^^^^^^^^^^^^^^^^^^^^
  File "<frozen importlib._bootstrap>", line 1206, in _gcd_import
  File "<frozen importlib._bootstrap>", line 1178, in _find_and_load
  File "<frozen importlib._bootstrap>", line 1128, in _find_and_load_unlocked
  File "<frozen importlib._bootstrap>", line 241, in _call_with_frames_removed
  File "<frozen importlib._bootstrap>", line 1206, in _gcd_import
  File "<frozen importlib._bootstrap>", line 1178, in _find_and_load
  File "<frozen importlib._bootstrap>", line 1142, in _find_and_load_unlocked
ModuleNotFoundError: No module named 'bace'
[2025-10-17 10:59:15 +0500] [237861] [INFO] Worker exiting (pid: 237861)
[2025-10-17 10:59:15 +0500] [237862] [INFO] Booting worker with pid: 237862
[2025-10-17 10:59:15 +0500] [237862] [ERROR] Exception in worker process
Traceback (most recent call last):
  File "/home/javodev/Shaxobiddin/KatDPI_TEST/KatDPI_test/env/lib/python3.11/site-packages/gunicorn/arbiter.py", line 608, in spawn_worker
    worker.init_process()
  File "/home/javodev/Shaxobiddin/KatDPI_TEST/KatDPI_test/env/lib/python3.11/site-packages/gunicorn/workers/base.py", line 135, in init_process
    self.load_wsgi()
  File "/home/javodev/Shaxobiddin/KatDPI_TEST/KatDPI_test/env/lib/python3.11/site-packages/gunicorn/workers/base.py", line 147, in load_wsgi
    self.wsgi = self.app.wsgi()
                ^^^^^^^^^^^^^^^
  File "/home/javodev/Shaxobiddin/KatDPI_TEST/KatDPI_test/env/lib/python3.11/site-packages/gunicorn/app/base.py", line 66, in wsgi
    self.callable = self.load()
                    ^^^^^^^^^^^
  File "/home/javodev/Shaxobiddin/KatDPI_TEST/KatDPI_test/env/lib/python3.11/site-packages/gunicorn/app/wsgiapp.py", line 57, in load
    return self.load_wsgiapp()
           ^^^^^^^^^^^^^^^^^^^
  File "/home/javodev/Shaxobiddin/KatDPI_TEST/KatDPI_test/env/lib/python3.11/site-packages/gunicorn/app/wsgiapp.py", line 47, in load_wsgiapp
    return util.import_app(self.app_uri)
           ^^^^^^^^^^^^^^^^^^^^^^^^^^^^^
  File "/home/javodev/Shaxobiddin/KatDPI_TEST/KatDPI_test/env/lib/python3.11/site-packages/gunicorn/util.py", line 370, in import_app
    mod = importlib.import_module(module)
          ^^^^^^^^^^^^^^^^^^^^^^^^^^^^^^^
  File "/usr/lib/python3.11/importlib/__init__.py", line 126, in import_module
    return _bootstrap._gcd_import(name[level:], package, level)
           ^^^^^^^^^^^^^^^^^^^^^^^^^^^^^^^^^^^^^^^^^^^^^^^^^^^^
  File "<frozen importlib._bootstrap>", line 1206, in _gcd_import
  File "<frozen importlib._bootstrap>", line 1178, in _find_and_load
  File "<frozen importlib._bootstrap>", line 1128, in _find_and_load_unlocked
  File "<frozen importlib._bootstrap>", line 241, in _call_with_frames_removed
  File "<frozen importlib._bootstrap>", line 1206, in _gcd_import
  File "<frozen importlib._bootstrap>", line 1178, in _find_and_load
  File "<frozen importlib._bootstrap>", line 1142, in _find_and_load_unlocked
ModuleNotFoundError: No module named 'bace'
[2025-10-17 10:59:15 +0500] [237862] [INFO] Worker exiting (pid: 237862)
[2025-10-17 10:59:15 +0500] [237859] [ERROR] Worker (pid:237861) exited with code 3
[2025-10-17 10:59:15 +0500] [237859] [ERROR] Worker (pid:237862) was sent SIGTERM!
[2025-10-17 10:59:16 +0500] [237859] [ERROR] Shutting down: Master
[2025-10-17 10:59:16 +0500] [237859] [ERROR] Reason: Worker failed to boot.
